<?xml version="1.0" ?>
<sdf version="1.9">
  <model name="mecanum_robot">

    <!-- BASE FOOTPRINT (虚拟链接) -->
    <link name="base_footprint">
      <inertial>
        <mass>0.001</mass>
        <inertia>
          <ixx>0.001</ixx>
          <iyy>0.001</iyy>
          <izz>0.001</izz>
        </inertia>
      </inertial>
    </link>

    <!-- CHASSIS -->
    <link name="chassis">
      <pose relative_to="base_footprint">0 0 0.225 0 0 0</pose>
      <inertial>
        <mass>15.0</mass>
        <inertia>
          <ixx>0.295</ixx>
          <iyy>0.645</iyy>
          <izz>0.850</izz>
        </inertia>
      </inertial>
      <visual name="chassis_visual">
        <geometry>
          <box>
            <size>0.6 0.4 0.15</size>
          </box>
        </geometry>
        <material>
          <ambient>0.35 0.35 0.35 1</ambient>
          <diffuse>0.35 0.35 0.35 1</diffuse>
        </material>
      </visual>
      <collision name="chassis_collision">
        <geometry>
          <box>
            <size>0.6 0.4 0.15</size>
          </box>
        </geometry>
      </collision>
    </link>

    <!-- BASE_FOOTPRINT TO CHASSIS JOINT -->
    <joint name="base_footprint_to_chassis" type="fixed">
      <parent>base_footprint</parent>
      <child>chassis</child>
    </joint>

    <!-- FRONT LEFT WHEEL -->
    <link name="front_left_wheel_link">
      <pose relative_to="chassis">0.25 0.25 -0.075 1.5707 0 0</pose>
      <inertial>
        <mass>0.5</mass>
        <inertia>
          <ixx>0.036458</ixx>
          <iyy>0.036458</iyy>
          <izz>0.03125</izz>
        </inertia>
      </inertial>
      <visual name="wheel_visual">
        <geometry>
          <cylinder>
            <radius>0.15</radius>
            <length>0.08</length>
          </cylinder>
        </geometry>
        <material>
          <ambient>0.1 0.1 0.1 1</ambient>
          <diffuse>0.1 0.1 0.1 1</diffuse>
        </material>
      </visual>
      <collision name="wheel_collision">
        <geometry>
          <cylinder>
            <radius>0.15</radius>
            <length>0.08</length>
          </cylinder>
        </geometry>
        <surface>
          <friction>
            <ode>
              <mu>1.5</mu>
              <mu2>0.5</mu2>
              <fdir1>1 -1 0</fdir1>
            </ode>
          </friction>
        </surface>
      </collision>
    </link>

    <joint name="front_left_wheel_joint" type="revolute">
      <parent>chassis</parent>
      <child>front_left_wheel_link</child>
      <axis>
        <xyz>0 0 1</xyz>
      </axis>
    </joint>

    <!-- FRONT RIGHT WHEEL -->
    <link name="front_right_wheel_link">
      <pose relative_to="chassis">0.25 -0.25 -0.075 1.5707 0 0</pose>
      <inertial>
        <mass>0.5</mass>
        <inertia>
          <ixx>0.036458</ixx>
          <iyy>0.036458</iyy>
          <izz>0.03125</izz>
        </inertia>
      </inertial>
      <visual name="wheel_visual">
        <geometry>
          <cylinder>
            <radius>0.15</radius>
            <length>0.08</length>
          </cylinder>
        </geometry>
        <material>
          <ambient>0.1 0.1 0.1 1</ambient>
          <diffuse>0.1 0.1 0.1 1</diffuse>
        </material>
      </visual>
      <collision name="wheel_collision">
        <geometry>
          <cylinder>
            <radius>0.15</radius>
            <length>0.08</length>
          </cylinder>
        </geometry>
        <surface>
          <friction>
            <ode>
              <mu>1.5</mu>
              <mu2>0.5</mu2>
              <fdir1>1 1 0</fdir1>
            </ode>
          </friction>
        </surface>
      </collision>
    </link>

    <joint name="front_right_wheel_joint" type="revolute">
      <parent>chassis</parent>
      <child>front_right_wheel_link</child>
      <axis>
        <xyz>0 0 1</xyz>
      </axis>
    </joint>

    <!-- REAR LEFT WHEEL -->
    <link name="rear_left_wheel_link">
      <pose relative_to="chassis">-0.25 0.25 -0.075 1.5707 0 0</pose>
      <inertial>
        <mass>0.5</mass>
        <inertia>
          <ixx>0.036458</ixx>
          <iyy>0.036458</iyy>
          <izz>0.03125</izz>
        </inertia>
      </inertial>
      <visual name="wheel_visual">
        <geometry>
          <cylinder>
            <radius>0.15</radius>
            <length>0.08</length>
          </cylinder>
        </geometry>
        <material>
          <ambient>0.1 0.1 0.1 1</ambient>
          <diffuse>0.1 0.1 0.1 1</diffuse>
        </material>
      </visual>
      <collision name="wheel_collision">
        <geometry>
          <cylinder>
            <radius>0.15</radius>
            <length>0.08</length>
          </cylinder>
        </geometry>
        <surface>
          <friction>
            <ode>
              <mu>1.5</mu>
              <mu2>0.5</mu2>
              <fdir1>1 -1 0</fdir1>
            </ode>
          </friction>
        </surface>
      </collision>
    </link>

    <joint name="rear_left_wheel_joint" type="revolute">
      <parent>chassis</parent>
      <child>rear_left_wheel_link</child>
      <axis>
        <xyz>0 0 1</xyz>
      </axis>
    </joint>

    <!-- REAR RIGHT WHEEL -->
    <link name="rear_right_wheel_link">
      <pose relative_to="chassis">-0.25 -0.25 -0.075 1.5707 0 0</pose>
      <inertial>
        <mass>0.5</mass>
        <inertia>
          <ixx>0.036458</ixx>
          <iyy>0.036458</iyy>
          <izz>0.03125</izz>
        </inertia>
      </inertial>
      <visual name="wheel_visual">
        <geometry>
          <cylinder>
            <radius>0.15</radius>
            <length>0.08</length>
          </cylinder>
        </geometry>
        <material>
          <ambient>0.1 0.1 0.1 1</ambient>
          <diffuse>0.1 0.1 0.1 1</diffuse>
        </material>
      </visual>
      <collision name="wheel_collision">
        <geometry>
          <cylinder>
            <radius>0.15</radius>
            <length>0.08</length>
          </cylinder>
        </geometry>
        <surface>
          <friction>
            <ode>
              <mu>1.5</mu>
              <mu2>0.5</mu2>
              <fdir1>1 1 0</fdir1>
            </ode>
          </friction>
        </surface>
      </collision>
    </link>

    <joint name="rear_right_wheel_joint" type="revolute">
      <parent>chassis</parent>
      <child>rear_right_wheel_link</child>
      <axis>
        <xyz>0 0 1</xyz>
      </axis>
    </joint>

    <!-- LIDAR -->
    <link name="livox_lidar">
      <pose relative_to="chassis">0.2 0 0.125 0 0 0</pose>
      <inertial>
        <mass>0.2</mass>
        <inertia>
          <ixx>0.001</ixx>
          <iyy>0.001</iyy>
          <izz>0.001</izz>
        </inertia>
      </inertial>
      <visual name="lidar_visual">
        <geometry>
          <cylinder>
            <radius>0.04</radius>
            <length>0.06</length>
          </cylinder>
        </geometry>
        <material>
          <ambient>0.1 0.1 0.1 1</ambient>
          <diffuse>0.1 0.1 0.1 1</diffuse>
        </material>
      </visual>
      <collision name="lidar_collision">
        <geometry>
          <cylinder>
            <radius>0.04</radius>
            <length>0.06</length>
          </cylinder>
        </geometry>
      </collision>
      <!-- LIDAR SENSOR -->
      <sensor name="lidar" type="gpu_lidar">
        <update_rate>10</update_rate>
        <lidar>
          <scan>
            <horizontal>
              <samples>360</samples>
              <resolution>1</resolution>
              <min_angle>-3.14159</min_angle>
              <max_angle>3.14159</max_angle>
            </horizontal>
            <vertical>
              <samples>1</samples>
              <resolution>1</resolution>
              <min_angle>0</min_angle>
              <max_angle>0</max_angle>
            </vertical>
          </scan>
          <range>
            <min>0.1</min>
            <max>30.0</max>
            <resolution>0.01</resolution>
          </range>
        </lidar>
      </sensor>
    </link>

    <joint name="lidar_joint" type="fixed">
      <parent>chassis</parent>
      <child>livox_lidar</child>
    </joint>

    <!-- IMU SENSOR ON CHASSIS -->
    <link name="imu_link">
      <pose relative_to="chassis">0 0 0 0 0 0</pose>
      <inertial>
        <mass>0.01</mass>
        <inertia>
          <ixx>0.001</ixx>
          <iyy>0.001</iyy>
          <izz>0.001</izz>
        </inertia>
      </inertial>
      <sensor name="imu_sensor" type="imu">
        <update_rate>100</update_rate>
        <imu>
          <angular_velocity>
            <x>
              <noise type="gaussian">
                <mean>0.0</mean>
                <stddev>2e-4</stddev>
              </noise>
            </x>
            <y>
              <noise type="gaussian">
                <mean>0.0</mean>
                <stddev>2e-4</stddev>
              </noise>
            </y>
            <z>
              <noise type="gaussian">
                <mean>0.0</mean>
                <stddev>2e-4</stddev>
              </noise>
            </z>
          </angular_velocity>
          <linear_acceleration>
            <x>
              <noise type="gaussian">
                <mean>0.0</mean>
                <stddev>1.7e-2</stddev>
              </noise>
            </x>
            <y>
              <noise type="gaussian">
                <mean>0.0</mean>
                <stddev>1.7e-2</stddev>
              </noise>
            </y>
            <z>
              <noise type="gaussian">
                <mean>0.0</mean>
                <stddev>1.7e-2</stddev>
              </noise>
            </z>
          </linear_acceleration>
        </imu>
      </sensor>
    </link>

    <joint name="imu_joint" type="fixed">
      <parent>chassis</parent>
      <child>imu_link</child>
    </joint>

    <!-- MECANUM DRIVE PLUGIN -->
    <plugin filename="gz-sim-mecanum-drive-system" name="gz::sim::systems::MecanumDrive">
      <front_left_joint>front_left_wheel_joint</front_left_joint>
      <front_right_joint>front_right_wheel_joint</front_right_joint>
      <back_left_joint>rear_left_wheel_joint</back_left_joint>
      <back_right_joint>rear_right_wheel_joint</back_right_joint>
      <wheel_separation>0.5</wheel_separation>
      <wheelbase>0.5</wheelbase>
      <wheel_radius>0.15</wheel_radius>
      <topic>/cmd_vel</topic>
      <tf_topic>/tf</tf_topic>
      <frame_id>odom</frame_id>
      <child_frame_id>base_footprint</child_frame_id>
    </plugin>

  </model>
</sdf>